mplus_output/bi-17-ELSA_W3.out
Mplus VERSION 8.1 (Mac)
MUTHEN & MUTHEN
04/23/2020  10:57 PM

INPUT INSTRUCTIONS

  DATA:
  FILE = "bi-17-ELSA_W3.dat";

  VARIABLE:
  NAMES = mplusid UDAT UDAY UMON UYER UIWR UDWR UANI ULET UPM3;
   MISSING=.;
   CATEGORICAL ARE all; idvariable = mplusid;
  ANALYSIS:
  estimator = wlsmv; coverage=0;
  MODEL:
  g by UDAT * ;
   g by UDAY * ;
   g by UMON * ;
   g by UYER * ;
   g by UIWR * ;
   g by UDWR * ;
   g by UANI * ;
   g by ULET * ;
   g by UPM3 * ;
   s1 by UIWR @ 1 ;
   s1 by UDWR @ 1 ;
   g @ 1;
   s1 * ;
   g with s1 @ 0 ;

  OUTPUT:
  standardized; svalues;



*** WARNING
  Data set contains cases with missing on all variables.
  These cases were not included in the analysis.
  Number of cases with missing on all variables:  274
   1 WARNING(S) FOUND IN THE INPUT INSTRUCTIONS




SUMMARY OF ANALYSIS

Number of groups                                                 1
Number of observations                                        9497

Number of dependent variables                                    9
Number of independent variables                                  0
Number of continuous latent variables                            2

Observed dependent variables

  Binary and ordered categorical (ordinal)
   UDAT        UDAY        UMON        UYER        UIWR        UDWR
   UANI        ULET        UPM3

Continuous latent variables
   G           S1

Variables with special functions

  ID variable           MPLUSID

Estimator                                                    WLSMV
Maximum number of iterations                                  1000
Convergence criterion                                    0.500D-04
Maximum number of steepest descent iterations                   20
Maximum number of iterations for H1                           2000
Convergence criterion for H1                             0.100D-03
Parameterization                                             DELTA
Link                                                        PROBIT

Input data file(s)
  bi-17-ELSA_W3.dat

Input data format  FREE


SUMMARY OF DATA

     Number of missing data patterns            16


COVARIANCE COVERAGE OF DATA

Minimum covariance coverage value   0.000


     PROPORTION OF DATA PRESENT


           Covariance Coverage
              UDAT          UDAY          UMON          UYER          UIWR
              ________      ________      ________      ________      ________
 UDAT           0.999
 UDAY           0.999         0.999
 UMON           0.999         0.999         0.999
 UYER           0.999         0.999         0.999         0.999
 UIWR           0.998         0.998         0.998         0.998         0.999
 UDWR           0.999         0.999         0.999         0.999         0.999
 UANI           0.997         0.997         0.997         0.997         0.997
 ULET           0.949         0.949         0.949         0.949         0.949
 UPM3           0.887         0.887         0.887         0.887         0.887


           Covariance Coverage
              UDWR          UANI          ULET          UPM3
              ________      ________      ________      ________
 UDWR           0.999
 UANI           0.998         0.998
 ULET           0.949         0.949         0.949
 UPM3           0.887         0.887         0.862         0.887


UNIVARIATE PROPORTIONS AND COUNTS FOR CATEGORICAL VARIABLES

    UDAT
      Category 1    0.181         1719.000
      Category 2    0.819         7769.000
    UDAY
      Category 1    0.022          205.000
      Category 2    0.978         9283.000
    UMON
      Category 1    0.026          250.000
      Category 2    0.974         9237.000
    UYER
      Category 1    0.023          220.000
      Category 2    0.977         9268.000
    UIWR
      Category 1    0.008           80.000
      Category 2    0.026          246.000
      Category 3    0.017          158.000
      Category 4    0.049          464.000
      Category 5    0.105          999.000
      Category 6    0.431         4086.000
      Category 7    0.205         1946.000
      Category 8    0.112         1058.000
      Category 9    0.040          381.000
      Category 10    0.007           67.000
    UDWR
      Category 1    0.067          633.000
      Category 2    0.040          382.000
      Category 3    0.057          540.000
      Category 4    0.113         1072.000
      Category 5    0.179         1701.000
      Category 6    0.374         3550.000
      Category 7    0.104          990.000
      Category 8    0.046          432.000
      Category 9    0.014          137.000
      Category 10    0.006           55.000
    UANI
      Category 1    0.017          163.000
      Category 2    0.006           56.000
      Category 3    0.024          226.000
      Category 4    0.097          918.000
      Category 5    0.191         1813.000
      Category 6    0.255         2421.000
      Category 7    0.203         1925.000
      Category 8    0.118         1118.000
      Category 9    0.057          544.000
      Category 10    0.031          296.000
    ULET
      Category 1    0.009           84.000
      Category 2    0.040          357.000
      Category 3    0.095          853.000
      Category 4    0.250         2253.000
      Category 5    0.238         2143.000
      Category 6    0.261         2355.000
      Category 7    0.050          455.000
      Category 8    0.030          267.000
      Category 9    0.013          115.000
      Category 10    0.015          134.000
    UPM3
      Category 1    0.030          255.000
      Category 2    0.251         2119.000
      Category 3    0.015          129.000
      Category 4    0.032          273.000
      Category 5    0.671         5652.000



THE MODEL ESTIMATION TERMINATED NORMALLY



MODEL FIT INFORMATION

Number of Free Parameters                       54

Chi-Square Test of Model Fit

          Value                            761.824*
          Degrees of Freedom                    26
          P-Value                           0.0000

*   The chi-square value for MLM, MLMV, MLR, ULSMV, WLSM and WLSMV cannot be used
    for chi-square difference testing in the regular way.  MLM, MLR and WLSM
    chi-square difference testing is described on the Mplus website.  MLMV, WLSMV,
    and ULSMV difference testing is done using the DIFFTEST option.

RMSEA (Root Mean Square Error Of Approximation)

          Estimate                           0.055
          90 Percent C.I.                    0.051  0.058
          Probability RMSEA <= .05           0.011

CFI/TLI

          CFI                                0.983
          TLI                                0.977

Chi-Square Test of Model Fit for the Baseline Model

          Value                          44572.104
          Degrees of Freedom                    36
          P-Value                           0.0000

SRMR (Standardized Root Mean Square Residual)

          Value                              0.058

Optimum Function Value for Weighted Least-Squares Estimator

          Value                     0.28842029D-01



MODEL RESULTS

                                                    Two-Tailed
                    Estimate       S.E.  Est./S.E.    P-Value

 G        BY
    UDAT               0.467      0.015     32.051      0.000
    UDAY               0.637      0.027     23.405      0.000
    UMON               0.766      0.021     36.420      0.000
    UYER               0.823      0.019     42.596      0.000
    UIWR               0.678      0.008     82.644      0.000
    UDWR               0.683      0.008     86.152      0.000
    UANI               0.678      0.008     82.393      0.000
    ULET               0.491      0.009     52.038      0.000
    UPM3               0.305      0.015     20.689      0.000

 S1       BY
    UIWR               1.000      0.000    999.000    999.000
    UDWR               1.000      0.000    999.000    999.000

 G        WITH
    S1                 0.000      0.000    999.000    999.000
