mplus_output/bi-18-ELSA_W4.out
Mplus VERSION 8.1 (Mac)
MUTHEN & MUTHEN
05/27/2020  10:28 PM

INPUT INSTRUCTIONS

  DATA:
  FILE = "bi-18-ELSA_W4.dat";

  VARIABLE:
  NAMES = mplusid UDAT UDAY UMON UYER UIWR UDWR UANI ULET URE2 URE3 URE4 URE5 URE6
       UPM3;
   MISSING=.;
   CATEGORICAL ARE all; idvariable = mplusid;
  ANALYSIS:
  estimator = wlsmv; coverage=0;
  MODEL:
  g by UDAT * ;
   g by UDAY * ;
   g by UMON * ;
   g by UYER * ;
   g by UIWR * ;
   g by UDWR * ;
   g by URE3 * ;
   g by URE5 * ;
   g by URE6 * ;
   g by UANI * ;
   g by ULET * ;
   g by URE2 * ;
   g by URE4 * ;
   g by UPM3 * ;
   s1 by UIWR @ 1 ;
   s1 by UDWR @ 1 ;
   g @ 1;
   s1 * ;
   g with s1 @ 0 ;

  OUTPUT:
  standardized; svalues;



*** WARNING
  Data set contains cases with missing on all variables.
  These cases were not included in the analysis.
  Number of cases with missing on all variables:  470
   1 WARNING(S) FOUND IN THE INPUT INSTRUCTIONS




SUMMARY OF ANALYSIS

Number of groups                                                 1
Number of observations                                       10580

Number of dependent variables                                   14
Number of independent variables                                  0
Number of continuous latent variables                            2

Observed dependent variables

  Binary and ordered categorical (ordinal)
   UDAT        UDAY        UMON        UYER        UIWR        UDWR
   UANI        ULET        URE2        URE3        URE4        URE5
   URE6        UPM3

Continuous latent variables
   G           S1

Variables with special functions

  ID variable           MPLUSID

Estimator                                                    WLSMV
Maximum number of iterations                                  1000
Convergence criterion                                    0.500D-04
Maximum number of steepest descent iterations                   20
Maximum number of iterations for H1                           2000
Convergence criterion for H1                             0.100D-03
Parameterization                                             DELTA
Link                                                        PROBIT

Input data file(s)
  bi-18-ELSA_W4.dat

Input data format  FREE


SUMMARY OF DATA

     Number of missing data patterns           101


COVARIANCE COVERAGE OF DATA

Minimum covariance coverage value   0.000


     PROPORTION OF DATA PRESENT


           Covariance Coverage
              UDAT          UDAY          UMON          UYER          UIWR
              ________      ________      ________      ________      ________
 UDAT           0.997
 UDAY           0.997         0.997
 UMON           0.997         0.997         0.997
 UYER           0.997         0.997         0.997         0.997
 UIWR           0.996         0.996         0.996         0.996         0.997
 UDWR           0.997         0.997         0.997         0.997         0.997
 UANI           0.996         0.996         0.996         0.996         0.995
 ULET           0.893         0.893         0.893         0.893         0.893
 URE2           0.974         0.974         0.974         0.974         0.974
 URE3           0.904         0.904         0.904         0.904         0.904
 URE4           0.724         0.724         0.724         0.724         0.724
 URE5           0.666         0.666         0.666         0.666         0.666
 URE6           0.664         0.664         0.664         0.664         0.664
 UPM3           0.894         0.894         0.894         0.894         0.893


           Covariance Coverage
              UDWR          UANI          ULET          URE2          URE3
              ________      ________      ________      ________      ________
 UDWR           0.999
 UANI           0.996         0.996
 ULET           0.893         0.893         0.893
 URE2           0.974         0.974         0.879         0.974
 URE3           0.904         0.904         0.820         0.898         0.904
 URE4           0.725         0.724         0.657         0.721         0.698
 URE5           0.666         0.666         0.605         0.663         0.649
 URE6           0.664         0.664         0.603         0.661         0.655
 UPM3           0.894         0.894         0.816         0.883         0.830


           Covariance Coverage
              URE4          URE5          URE6          UPM3
              ________      ________      ________      ________
 URE4           0.725
 URE5           0.561         0.666
 URE6           0.555         0.524         0.664
 UPM3           0.672         0.621         0.622         0.894


UNIVARIATE PROPORTIONS AND COUNTS FOR CATEGORICAL VARIABLES

    UDAT
      Category 1    0.177         1872.000
      Category 2    0.823         8680.000
    UDAY
      Category 1    0.019          201.000
      Category 2    0.981        10351.000
    UMON
      Category 1    0.022          236.000
      Category 2    0.978        10316.000
    UYER
      Category 1    0.022          229.000
      Category 2    0.978        10323.000
    UIWR
      Category 1    0.009           96.000
      Category 2    0.018          194.000
      Category 3    0.018          194.000
      Category 4    0.042          448.000
      Category 5    0.109         1147.000
      Category 6    0.437         4608.000
      Category 7    0.202         2126.000
      Category 8    0.114         1203.000
      Category 9    0.041          432.000
      Category 10    0.009           96.000
    UDWR
      Category 1    0.062          652.000
      Category 2    0.035          375.000
      Category 3    0.057          600.000
      Category 4    0.118         1247.000
      Category 5    0.185         1955.000
      Category 6    0.374         3950.000
      Category 7    0.097         1026.000
      Category 8    0.048          511.000
      Category 9    0.018          194.000
      Category 10    0.006           61.000
    UANI
      Category 1    0.014          150.000
      Category 2    0.008           83.000
      Category 3    0.020          211.000
      Category 4    0.082          864.000
      Category 5    0.192         2022.000
      Category 6    0.242         2549.000
      Category 7    0.217         2285.000
      Category 8    0.127         1338.000
      Category 9    0.063          667.000
      Category 10    0.035          372.000
    ULET
      Category 1    0.009           84.000
      Category 2    0.033          313.000
      Category 3    0.089          843.000
      Category 4    0.241         2278.000
      Category 5    0.244         2308.000
      Category 6    0.277         2618.000
      Category 7    0.050          475.000
      Category 8    0.033          314.000
      Category 9    0.011          108.000
      Category 10    0.012          112.000
    URE2
      Category 1    0.009           88.000
      Category 2    0.991        10222.000
    URE3
      Category 1    0.061          583.000
      Category 2    0.939         8983.000
    URE4
      Category 1    0.188         1439.000
      Category 2    0.812         6227.000
    URE5
      Category 1    0.182         1283.000
      Category 2    0.818         5763.000
    URE6
      Category 1    0.136          953.000
      Category 2    0.552         3881.000
      Category 3    0.312         2193.000
    UPM3
      Category 1    0.027          251.000
      Category 2    0.238         2254.000
      Category 3    0.011          100.000
      Category 4    0.031          293.000
      Category 5    0.693         6557.000



THE MODEL ESTIMATION TERMINATED NORMALLY



MODEL FIT INFORMATION

Number of Free Parameters                       65

Chi-Square Test of Model Fit

          Value                           1216.063*
          Degrees of Freedom                    76
          P-Value                           0.0000

*   The chi-square value for MLM, MLMV, MLR, ULSMV, WLSM and WLSMV cannot be used
    for chi-square difference testing in the regular way.  MLM, MLR and WLSM
